<sdf version="1.7">
  <model name="avatar">
    <link name="root">
      <inertial>
        <pose>0 0 0.8854 0 -0 0</pose>
        <mass>8.36</mass>
        <inertia>
          <ixx>0.2</ixx>
          <ixy>0</ixy>
          <ixz>1.22465e-17</ixz>
          <iyy>0.4</iyy>
          <iyz>0</iyz>
          <izz>0.4</izz>
        </inertia>
      </inertial>
    </link>
    <joint name="pelvis_yaw_to_pelvis_pitch" type="revolute">
      <pose relative_to="root">0 0 0.8854 3.14159 -1.57079 3.14159</pose>
      <parent>root</parent>
      <child>pelvis_pitch</child>
      <axis>
        <xyz>0 1 0</xyz>
        <limit>
          <lower>-1.5708</lower>
          <upper>2.44346</upper>
          <effort>1</effort>
          <velocity>1</velocity>
        </limit>
        <dynamics>
          <spring_reference>0</spring_reference>
          <spring_stiffness>0</spring_stiffness>
        </dynamics>
      </axis>
    </joint>
    <link name="pelvis_pitch">
      <pose relative_to="pelvis_yaw_to_pelvis_pitch">0 0 0 0 -0 0</pose>
      <inertial>
        <pose>0 0 0 0 -0 0</pose>
        <mass>8.36</mass>
        <inertia>
          <ixx>0.4</ixx>
          <ixy>0</ixy>
          <ixz>0</ixz>
          <iyy>0.4</iyy>
          <iyz>0</iyz>
          <izz>0.2</izz>
        </inertia>
      </inertial>
    </link>
    <joint name="pelvis_pitch_to_pelvis" type="revolute">
      <pose relative_to="pelvis_pitch">0 0 0 0 -0 0</pose>
      <parent>pelvis_pitch</parent>
      <child>pelvis</child>
      <axis>
        <xyz>1 0 0</xyz>
        <limit>
          <lower>-1.5708</lower>
          <upper>2.44346</upper>
          <effort>1</effort>
          <velocity>1</velocity>
        </limit>
        <dynamics>
          <spring_reference>0</spring_reference>
          <spring_stiffness>0</spring_stiffness>
        </dynamics>
      </axis>
    </joint>
    <link name="pelvis">
      <pose relative_to="pelvis_pitch_to_pelvis">0 0 0 0 -0 0</pose>
      <inertial>
        <pose>0 0 0 0 -0 0</pose>
        <mass>8.36</mass>
        <inertia>
          <ixx>0.4</ixx>
          <ixy>0</ixy>
          <ixz>0</ixz>
          <iyy>0.4</iyy>
          <iyz>0</iyz>
          <izz>0.2</izz>
        </inertia>
      </inertial>
      <collision name="pelvis_collision">
        <pose>0 0 0 0 -0 0</pose>
        <geometry>
          <mesh>
            <scale>1 1 1</scale>
            <uri>model://iai_avatar_description/avatars/MetaHuman/meshes/fbx/pelvis.fbx</uri>
          </mesh>
        </geometry>
      </collision>
      <visual name="pelvis_visual">
        <pose>0 0 0 0 -0 0</pose>
        <geometry>
          <mesh>
            <scale>1 1 1</scale>
            <uri>model://iai_avatar_description/avatars/MetaHuman/meshes/fbx/pelvis.fbx</uri>
          </mesh>
        </geometry>
      </visual>
    </link>
    <joint name="pelvis_to_spine_01_yaw" type="revolute">
      <pose relative_to="pelvis">0.020312 0 0 0 -0 0</pose>
      <parent>pelvis</parent>
      <child>spine_01</child>
      <axis>
        <xyz>1 0 0</xyz>
        <limit>
          <lower>0</lower>
          <upper>0</upper>
          <effort>1</effort>
          <velocity>1</velocity>
        </limit>
        <dynamics>
          <spring_reference>0</spring_reference>
          <spring_stiffness>0</spring_stiffness>
        </dynamics>
      </axis>
    </joint>
    <link name="spine_01">
      <pose relative_to="pelvis_to_spine_01_yaw">0 0 0 0 -0 0</pose>
      <inertial>
        <pose>0 0 0 0 -0 0</pose>
        <mass>2.34</mass>
        <inertia>
          <ixx>0.4</ixx>
          <ixy>0</ixy>
          <ixz>0</ixz>
          <iyy>0.4</iyy>
          <iyz>0</iyz>
          <izz>0.2</izz>
        </inertia>
      </inertial>
    </link>
    <joint name="spine_01_to_spine_02" type="revolute">
      <pose relative_to="spine_01">0.042 0 0 0 -0 0</pose>
      <parent>spine_01</parent>
      <child>spine_02</child>
      <axis>
        <xyz>1 0 0</xyz>
        <limit>
          <lower>-1e+16</lower>
          <upper>1e+16</upper>
        </limit>
        <dynamics>
          <damping>1</damping>
          <friction>0.0001</friction>
          <spring_reference>0</spring_reference>
          <spring_stiffness>0</spring_stiffness>
        </dynamics>
      </axis>
    </joint>
    <link name="spine_02">
      <pose relative_to="spine_01_to_spine_02">0 0 0 0 -0 0</pose>
      <inertial>
        <pose>0 0 0 0 -0 0</pose>
        <mass>3.34</mass>
        <inertia>
          <ixx>0.4</ixx>
          <ixy>0</ixy>
          <ixz>0</ixz>
          <iyy>0.4</iyy>
          <iyz>0</iyz>
          <izz>0.2</izz>
        </inertia>
      </inertial>
    </link>
    <joint name="spine_02_to_spine_03" type="revolute">
      <pose relative_to="spine_02">0.067 0 0 0 -0 0</pose>
      <parent>spine_02</parent>
      <child>spine_03</child>
      <axis>
        <xyz>1 0 0</xyz>
        <limit>
          <lower>0</lower>
          <upper>0</upper>
          <effort>1</effort>
          <velocity>1</velocity>
        </limit>
        <dynamics>
          <spring_reference>0</spring_reference>
          <spring_stiffness>0</spring_stiffness>
        </dynamics>
      </axis>
    </joint>
    <link name="spine_03">
      <pose relative_to="spine_02_to_spine_03">0 0 0 0 -0 0</pose>
      <inertial>
        <pose>0 0 0 0 -0 0</pose>
        <mass>4.43</mass>
        <inertia>
          <ixx>0.4</ixx>
          <ixy>0</ixy>
          <ixz>0</ixz>
          <iyy>0.4</iyy>
          <iyz>0</iyz>
          <izz>0.2</izz>
        </inertia>
      </inertial>
    </link>
    <joint name="spine_03_to_spine_04_yaw" type="revolute">
      <pose relative_to="spine_03">0.07891 0 0 0 -0 0</pose>
      <parent>spine_03</parent>
      <child>spine_04_yaw</child>
      <axis>
        <xyz>1 0 0</xyz>
        <limit>
          <lower>0</lower>
          <upper>0</upper>
          <effort>1</effort>
          <velocity>1</velocity>
        </limit>
        <dynamics>
          <spring_reference>0</spring_reference>
          <spring_stiffness>0</spring_stiffness>
        </dynamics>
      </axis>
    </joint>
    <link name="spine_04_yaw">
      <pose relative_to="spine_03_to_spine_04_yaw">0 0 0 0 -0 0</pose>
      <inertial>
        <pose>0 0 0 0 -0 0</pose>
        <mass>5.43</mass>
        <inertia>
          <ixx>0.4</ixx>
          <ixy>0</ixy>
          <ixz>0</ixz>
          <iyy>0.4</iyy>
          <iyz>0</iyz>
          <izz>0.2</izz>
        </inertia>
      </inertial>
    </link>
    <joint name="spine_04_yaw_to_spine_04_pitch" type="revolute">
      <pose relative_to="spine_04_yaw">0 0 0 0 -0 0</pose>
      <parent>spine_04_yaw</parent>
      <child>spine_04_pitch</child>
      <axis>
        <xyz>0 1 0</xyz>
        <limit>
          <lower>-1.5708</lower>
          <upper>2.44346</upper>
          <effort>1</effort>
          <velocity>1</velocity>
        </limit>
        <dynamics>
          <spring_reference>0</spring_reference>
          <spring_stiffness>0</spring_stiffness>
        </dynamics>
      </axis>
    </joint>
    <link name="spine_04_pitch">
      <pose relative_to="spine_04_yaw_to_spine_04_pitch">0 0 0 0 -0 0</pose>
      <inertial>
        <pose>0 0 0 0 -0 0</pose>
        <mass>5.43</mass>
        <inertia>
          <ixx>0.4</ixx>
          <ixy>0</ixy>
          <ixz>0</ixz>
          <iyy>0.4</iyy>
          <iyz>0</iyz>
          <izz>0.2</izz>
        </inertia>
      </inertial>
    </link>
    <joint name="spine_04_pitch_to_spine_04" type="revolute">
      <pose relative_to="spine_04_pitch">0 0 0 0 -0 0</pose>
      <parent>spine_04_pitch</parent>
      <child>spine_04</child>
      <axis>
        <xyz>1 0 0</xyz>
        <limit>
          <lower>-1.5708</lower>
          <upper>2.44346</upper>
          <effort>1</effort>
          <velocity>1</velocity>
        </limit>
        <dynamics>
          <spring_reference>0</spring_reference>
          <spring_stiffness>0</spring_stiffness>
        </dynamics>
      </axis>
    </joint>
    <link name="spine_04">
      <pose relative_to="spine_04_pitch_to_spine_04">0 0 0 0 -0 0</pose>
      <inertial>
        <pose>0 0 0 0 -0 0</pose>
        <mass>5.43</mass>
        <inertia>
          <ixx>0.4</ixx>
          <ixy>0</ixy>
          <ixz>0</ixz>
          <iyy>0.4</iyy>
          <iyz>0</iyz>
          <izz>0.2</izz>
        </inertia>
      </inertial>
      <collision name="spine_04_collision">
        <pose>0 0 0 0 -0 0</pose>
        <geometry>
          <mesh>
            <scale>1 1 1</scale>
            <uri>model://iai_avatar_description/avatars/MetaHuman/meshes/fbx/torso.fbx</uri>
          </mesh>
        </geometry>
      </collision>
      <visual name="spine_04_visual">
        <pose>0 0 0 0 -0 0</pose>
        <geometry>
          <mesh>
            <scale>1 1 1</scale>
            <uri>model://iai_avatar_description/avatars/MetaHuman/meshes/fbx/torso.fbx</uri>
          </mesh>
        </geometry>
      </visual>
    </link>
    <joint name="spine_04_to_spine_05" type="revolute">
      <pose relative_to="spine_04">0.150384 0 0 0 -0 0</pose>
      <parent>spine_04</parent>
      <child>spine_05</child>
      <axis>
        <xyz>1 0 0</xyz>
        <limit>
          <lower>-1e+16</lower>
          <upper>1e+16</upper>
        </limit>
        <dynamics>
          <damping>1</damping>
          <friction>0.0001</friction>
          <spring_reference>0</spring_reference>
          <spring_stiffness>0</spring_stiffness>
        </dynamics>
      </axis>
    </joint>
    <link name="spine_05">
      <pose relative_to="spine_04_to_spine_05">0 0 0 0 -0 0</pose>
      <inertial>
        <pose>0 0 0 0 -0 0</pose>
        <mass>6.05</mass>
        <inertia>
          <ixx>0.4</ixx>
          <ixy>0</ixy>
          <ixz>0</ixz>
          <iyy>0.4</iyy>
          <iyz>0</iyz>
          <izz>0.2</izz>
        </inertia>
      </inertial>
    </link>
    <joint name="spine_05_to_clavicle_l" type="revolute">
      <pose relative_to="spine_05">0.051428 0.008832 -0.008165 3.14159 1.57079 3.14159</pose>
      <parent>spine_05</parent>
      <child>clavicle_l</child>
      <axis>
        <xyz>0 1 0</xyz>
        <limit>
          <lower>-1.5708</lower>
          <upper>2.44346</upper>
          <effort>1</effort>
          <velocity>1</velocity>
        </limit>
        <dynamics>
          <damping>1</damping>
          <friction>0.0001</friction>
          <spring_reference>0</spring_reference>
          <spring_stiffness>0</spring_stiffness>
        </dynamics>
      </axis>
    </joint>
    <link name="clavicle_l">
      <pose relative_to="spine_05_to_clavicle_l">0 0 0 0 -0 0</pose>
      <inertial>
        <pose>0 0 0 0 -0 0</pose>
        <mass>2.08</mass>
        <inertia>
          <ixx>0.4</ixx>
          <ixy>0</ixy>
          <ixz>0</ixz>
          <iyy>0.4</iyy>
          <iyz>0</iyz>
          <izz>0.2</izz>
        </inertia>
      </inertial>
    </link>
    <joint name="clavicle_l_to_upperarm_l_yaw" type="revolute">
      <pose relative_to="clavicle_l">0.1334 0 0 0 1.0472 0</pose>
      <parent>clavicle_l</parent>
      <child>upperarm_l_yaw</child>
      <axis>
        <xyz>0 0 1</xyz>
        <limit>
          <lower>-1.5708</lower>
          <upper>2.44346</upper>
          <effort>1</effort>
          <velocity>1</velocity>
        </limit>
        <dynamics>
          <damping>1</damping>
          <friction>0.0001</friction>
          <spring_reference>0</spring_reference>
          <spring_stiffness>0</spring_stiffness>
        </dynamics>
      </axis>
    </joint>
    <link name="upperarm_l_yaw">
      <pose relative_to="clavicle_l_to_upperarm_l_yaw">0 0 0 0 -0 0</pose>
      <inertial>
        <pose>0 0 0 0 -0 0</pose>
        <mass>1.75</mass>
        <inertia>
          <ixx>0.4</ixx>
          <ixy>0</ixy>
          <ixz>0</ixz>
          <iyy>0.4</iyy>
          <iyz>0</iyz>
          <izz>0.2</izz>
        </inertia>
      </inertial>
    </link>
    <joint name="upperarm_l_yaw_to_upperarm_l_pitch" type="revolute">
      <pose relative_to="upperarm_l_yaw">0 0 0 0 -0 0</pose>
      <parent>upperarm_l_yaw</parent>
      <child>upperarm_l_pitch</child>
      <axis>
        <xyz>0 1 0</xyz>
        <limit>
          <lower>-1.5708</lower>
          <upper>2.44346</upper>
          <effort>1</effort>
          <velocity>1</velocity>
        </limit>
        <dynamics>
          <spring_reference>0</spring_reference>
          <spring_stiffness>0</spring_stiffness>
        </dynamics>
      </axis>
    </joint>
    <link name="upperarm_l_pitch">
      <pose relative_to="upperarm_l_yaw_to_upperarm_l_pitch">0 0 0 0 -0 0</pose>
      <inertial>
        <pose>0 0 0 0 -0 0</pose>
        <mass>1.75</mass>
        <inertia>
          <ixx>0.4</ixx>
          <ixy>0</ixy>
          <ixz>0</ixz>
          <iyy>0.4</iyy>
          <iyz>0</iyz>
          <izz>0.2</izz>
        </inertia>
      </inertial>
    </link>
    <joint name="upperarm_l_pitch_to_upperarm_l" type="revolute">
      <pose relative_to="upperarm_l_pitch">0 0 0 0 -0 0</pose>
      <parent>upperarm_l_pitch</parent>
      <child>upperarm_l</child>
      <axis>
        <xyz>1 0 0</xyz>
        <limit>
          <lower>-1.5708</lower>
          <upper>2.44346</upper>
          <effort>1</effort>
          <velocity>1</velocity>
        </limit>
        <dynamics>
          <spring_reference>0</spring_reference>
          <spring_stiffness>0</spring_stiffness>
        </dynamics>
      </axis>
    </joint>
    <link name="upperarm_l">
      <pose relative_to="upperarm_l_pitch_to_upperarm_l">0 0 0 0 -0 0</pose>
      <inertial>
        <pose>0 0 0 0 -0 0</pose>
        <mass>1.75</mass>
        <inertia>
          <ixx>0.4</ixx>
          <ixy>0</ixy>
          <ixz>0</ixz>
          <iyy>0.4</iyy>
          <iyz>0</iyz>
          <izz>0.2</izz>
        </inertia>
      </inertial>
      <collision name="upperarm_l_collision">
        <pose>0 0 0 0 -0 0</pose>
        <geometry>
          <mesh>
            <scale>1 1 1</scale>
            <uri>model://iai_avatar_description/avatars/MetaHuman/meshes/fbx/upperarm_l.fbx</uri>
          </mesh>
        </geometry>
      </collision>
      <visual name="upperarm_l_visual">
        <pose>0 0 0 0 -0 0</pose>
        <geometry>
          <mesh>
            <scale>1 1 1</scale>
            <uri>model://iai_avatar_description/avatars/MetaHuman/meshes/fbx/upperarm_l.fbx</uri>
          </mesh>
        </geometry>
      </visual>
    </link>
    <joint name="upperarm_l_to_lowerarm_l_yaw" type="revolute">
      <pose relative_to="upperarm_l">0.238538 0 0 0 -0 0</pose>
      <parent>upperarm_l</parent>
      <child>lowerarm_l_yaw</child>
      <axis>
        <xyz>1 0 0</xyz>
        <limit>
          <lower>-1e+16</lower>
          <upper>1e+16</upper>
        </limit>
        <dynamics>
          <spring_reference>0</spring_reference>
          <spring_stiffness>0</spring_stiffness>
        </dynamics>
      </axis>
    </joint>
    <link name="lowerarm_l_yaw">
      <pose relative_to="upperarm_l_to_lowerarm_l_yaw">0 0 0 0 -0 0</pose>
      <inertial>
        <pose>0 0 0 0 -0 0</pose>
        <mass>1.39</mass>
        <inertia>
          <ixx>0.4</ixx>
          <ixy>0</ixy>
          <ixz>0</ixz>
          <iyy>0.4</iyy>
          <iyz>0</iyz>
          <izz>0.2</izz>
        </inertia>
      </inertial>
    </link>
    <joint name="lowerarm_l_yaw_to_lowerarm_l_pitch" type="revolute">
      <pose relative_to="lowerarm_l_yaw">0 0 0 0 -0 0</pose>
      <parent>lowerarm_l_yaw</parent>
      <child>lowerarm_l_pitch</child>
      <axis>
        <xyz>0 1 0</xyz>
        <limit>
          <lower>-1.5708</lower>
          <upper>2.44346</upper>
          <effort>1</effort>
          <velocity>1</velocity>
        </limit>
        <dynamics>
          <spring_reference>0</spring_reference>
          <spring_stiffness>0</spring_stiffness>
        </dynamics>
      </axis>
    </joint>
    <link name="lowerarm_l_pitch">
      <pose relative_to="lowerarm_l_yaw_to_lowerarm_l_pitch">0 0 0 0 -0 0</pose>
      <inertial>
        <pose>0 0 0 0 -0 0</pose>
        <mass>1.39</mass>
        <inertia>
          <ixx>0.4</ixx>
          <ixy>0</ixy>
          <ixz>0</ixz>
          <iyy>0.4</iyy>
          <iyz>0</iyz>
          <izz>0.2</izz>
        </inertia>
      </inertial>
    </link>
    <joint name="lowerarm_l_pitch_to_lowerarm_l" type="revolute">
      <pose relative_to="lowerarm_l_pitch">0 0 0 0 -0 0</pose>
      <parent>lowerarm_l_pitch</parent>
      <child>lowerarm_l</child>
      <axis>
        <xyz>1 0 0</xyz>
        <limit>
          <lower>-1.5708</lower>
          <upper>2.44346</upper>
          <effort>1</effort>
          <velocity>1</velocity>
        </limit>
        <dynamics>
          <spring_reference>0</spring_reference>
          <spring_stiffness>0</spring_stiffness>
        </dynamics>
      </axis>
    </joint>
    <link name="lowerarm_l">
      <pose relative_to="lowerarm_l_pitch_to_lowerarm_l">0 0 0 0 -0 0</pose>
      <inertial>
        <pose>0 0 0 0 -0 0</pose>
        <mass>1.39</mass>
        <inertia>
          <ixx>0.4</ixx>
          <ixy>0</ixy>
          <ixz>0</ixz>
          <iyy>0.4</iyy>
          <iyz>0</iyz>
          <izz>0.2</izz>
        </inertia>
      </inertial>
      <collision name="lowerarm_l_collision">
        <pose>0 0 0 0 -0 0</pose>
        <geometry>
          <mesh>
            <scale>1 1 1</scale>
            <uri>model://iai_avatar_description/avatars/MetaHuman/meshes/fbx/lowerarm_l.fbx</uri>
          </mesh>
        </geometry>
      </collision>
      <visual name="lowerarm_l_visual">
        <pose>0 0 0 0 -0 0</pose>
        <geometry>
          <mesh>
            <scale>1 1 1</scale>
            <uri>model://iai_avatar_description/avatars/MetaHuman/meshes/fbx/lowerarm_l.fbx</uri>
          </mesh>
        </geometry>
      </visual>
    </link>
    <joint name="lowerarm_l_to_hand_l_yaw" type="revolute">
      <pose relative_to="lowerarm_l">0.22966 0 -0 -1.2351 0.1883 -0.2033</pose>
      <parent>lowerarm_l</parent>
      <child>hand_l_yaw</child>
      <axis>
        <xyz>1 0 0</xyz>
        <limit>
          <lower>-1e+16</lower>
          <upper>1e+16</upper>
        </limit>
        <dynamics>
          <damping>1</damping>
          <friction>0.0001</friction>
          <spring_reference>0</spring_reference>
          <spring_stiffness>0</spring_stiffness>
        </dynamics>
      </axis>
    </joint>
    <link name="hand_l_yaw">
      <pose relative_to="lowerarm_l_to_hand_l_yaw">0 0 0 0 -0 0</pose>
      <inertial>
        <pose>0 0 0 0 -0 0</pose>
        <mass>1.56</mass>
        <inertia>
          <ixx>0.4</ixx>
          <ixy>0</ixy>
          <ixz>0</ixz>
          <iyy>0.4</iyy>
          <iyz>0</iyz>
          <izz>0.2</izz>
        </inertia>
      </inertial>
    </link>
    <joint name="hand_l_yaw_to_hand_l_pitch" type="revolute">
      <pose relative_to="hand_l_yaw">0 0 0 0 -0 0</pose>
      <parent>hand_l_yaw</parent>
      <child>hand_l_pitch</child>
      <axis>
        <xyz>0 1 0</xyz>
        <limit>
          <lower>-1.5708</lower>
          <upper>2.44346</upper>
          <effort>1</effort>
          <velocity>1</velocity>
        </limit>
        <dynamics>
          <spring_reference>0</spring_reference>
          <spring_stiffness>0</spring_stiffness>
        </dynamics>
      </axis>
    </joint>
    <link name="hand_l_pitch">
      <pose relative_to="hand_l_yaw_to_hand_l_pitch">0 0 0 0 -0 0</pose>
      <inertial>
        <pose>0 0 0 0 -0 0</pose>
        <mass>1.56</mass>
        <inertia>
          <ixx>0.4</ixx>
          <ixy>0</ixy>
          <ixz>0</ixz>
          <iyy>0.4</iyy>
          <iyz>0</iyz>
          <izz>0.2</izz>
        </inertia>
      </inertial>
    </link>
    <joint name="hand_l_pitch_to_hand_l" type="revolute">
      <pose relative_to="hand_l_pitch">0 0 0 0 -0 0</pose>
      <parent>hand_l_pitch</parent>
      <child>hand_l</child>
      <axis>
        <xyz>1 0 0</xyz>
        <limit>
          <lower>-1.5708</lower>
          <upper>2.44346</upper>
          <effort>1</effort>
          <velocity>1</velocity>
        </limit>
        <dynamics>
          <spring_reference>0</spring_reference>
          <spring_stiffness>0</spring_stiffness>
        </dynamics>
      </axis>
    </joint>
    <link name="hand_l">
      <pose relative_to="hand_l_pitch_to_hand_l">0 0 0 0 -0 0</pose>
      <inertial>
        <pose>0 0 0 0 -0 0</pose>
        <mass>1.56</mass>
        <inertia>
          <ixx>0.4</ixx>
          <ixy>0</ixy>
          <ixz>0</ixz>
          <iyy>0.4</iyy>
          <iyz>0</iyz>
          <izz>0.2</izz>
        </inertia>
      </inertial>
      <collision name="hand_l_collision">
        <pose>0 0 0 0 -0 0</pose>
        <geometry>
          <mesh>
            <scale>1 1 1</scale>
            <uri>model://iai_avatar_description/avatars/MetaHuman/meshes/fbx/hand_l.fbx</uri>
          </mesh>
        </geometry>
      </collision>
      <visual name="hand_l_visual">
        <pose>0 0 0 0 -0 0</pose>
        <geometry>
          <mesh>
            <scale>1 1 1</scale>
            <uri>model://iai_avatar_description/avatars/MetaHuman/meshes/fbx/hand_l.fbx</uri>
          </mesh>
        </geometry>
      </visual>
    </link>
    <joint name="spine_05_to_clavicle_r" type="revolute">
      <pose relative_to="spine_05">0.051428 0.008832 0.008165 -3e-06 1.57079 3.14159</pose>
      <parent>spine_05</parent>
      <child>clavicle_r</child>
      <axis>
        <xyz>1 0 0</xyz>
        <limit>
          <lower>-1e+16</lower>
          <upper>1e+16</upper>
        </limit>
        <dynamics>
          <damping>1</damping>
          <friction>0.0001</friction>
          <spring_reference>0</spring_reference>
          <spring_stiffness>0</spring_stiffness>
        </dynamics>
      </axis>
    </joint>
    <link name="clavicle_r">
      <pose relative_to="spine_05_to_clavicle_r">0 0 0 0 -0 0</pose>
      <inertial>
        <pose>0 0 0 0 -0 0</pose>
        <mass>2.09</mass>
        <inertia>
          <ixx>0.4</ixx>
          <ixy>0</ixy>
          <ixz>0</ixz>
          <iyy>0.4</iyy>
          <iyz>0</iyz>
          <izz>0.2</izz>
        </inertia>
      </inertial>
    </link>
    <joint name="clavicle_r_to_upperarm_r_yaw" type="revolute">
      <pose relative_to="clavicle_r">-0.1334 0 0 0 1.0472 0</pose>
      <parent>clavicle_r</parent>
      <child>upperarm_r_yaw</child>
      <axis>
        <xyz>1 0 0</xyz>
        <limit>
          <lower>-1e+16</lower>
          <upper>1e+16</upper>
        </limit>
        <dynamics>
          <damping>1</damping>
          <friction>0.0001</friction>
          <spring_reference>0</spring_reference>
          <spring_stiffness>0</spring_stiffness>
        </dynamics>
      </axis>
    </joint>
    <link name="upperarm_r_yaw">
      <pose relative_to="clavicle_r_to_upperarm_r_yaw">0 0 0 0 -0 0</pose>
      <inertial>
        <pose>0 0 0 0 -0 0</pose>
        <mass>1.75</mass>
        <inertia>
          <ixx>0.4</ixx>
          <ixy>0</ixy>
          <ixz>0</ixz>
          <iyy>0.4</iyy>
          <iyz>0</iyz>
          <izz>0.2</izz>
        </inertia>
      </inertial>
    </link>
    <joint name="upperarm_r_yaw_to_upperarm_r_pitch" type="revolute">
      <pose relative_to="upperarm_r_yaw">0 0 0 0 -0 0</pose>
      <parent>upperarm_r_yaw</parent>
      <child>upperarm_r_pitch</child>
      <axis>
        <xyz>0 1 0</xyz>
        <limit>
          <lower>-1.5708</lower>
          <upper>2.44346</upper>
          <effort>1</effort>
          <velocity>1</velocity>
        </limit>
        <dynamics>
          <spring_reference>0</spring_reference>
          <spring_stiffness>0</spring_stiffness>
        </dynamics>
      </axis>
    </joint>
    <link name="upperarm_r_pitch">
      <pose relative_to="upperarm_r_yaw_to_upperarm_r_pitch">0 0 0 0 -0 0</pose>
      <inertial>
        <pose>0 0 0 0 -0 0</pose>
        <mass>1.75</mass>
        <inertia>
          <ixx>0.4</ixx>
          <ixy>0</ixy>
          <ixz>0</ixz>
          <iyy>0.4</iyy>
          <iyz>0</iyz>
          <izz>0.2</izz>
        </inertia>
      </inertial>
    </link>
    <joint name="upperarm_r_pitch_to_upperarm_r" type="revolute">
      <pose relative_to="upperarm_r_pitch">0 0 0 0 -0 0</pose>
      <parent>upperarm_r_pitch</parent>
      <child>upperarm_r</child>
      <axis>
        <xyz>1 0 0</xyz>
        <limit>
          <lower>-1.5708</lower>
          <upper>2.44346</upper>
          <effort>1</effort>
          <velocity>1</velocity>
        </limit>
        <dynamics>
          <spring_reference>0</spring_reference>
          <spring_stiffness>0</spring_stiffness>
        </dynamics>
      </axis>
    </joint>
    <link name="upperarm_r">
      <pose relative_to="upperarm_r_pitch_to_upperarm_r">0 0 0 0 -0 0</pose>
      <inertial>
        <pose>0 0 0 0 -0 0</pose>
        <mass>1.75</mass>
        <inertia>
          <ixx>0.4</ixx>
          <ixy>0</ixy>
          <ixz>0</ixz>
          <iyy>0.4</iyy>
          <iyz>0</iyz>
          <izz>0.2</izz>
        </inertia>
      </inertial>
      <collision name="upperarm_r_collision">
        <pose>0 0 0 0 -0 0</pose>
        <geometry>
          <mesh>
            <scale>1 1 1</scale>
            <uri>model://iai_avatar_description/avatars/MetaHuman/meshes/fbx/upperarm_r.fbx</uri>
          </mesh>
        </geometry>
      </collision>
      <visual name="upperarm_r_visual">
        <pose>0 0 0 0 -0 0</pose>
        <geometry>
          <mesh>
            <scale>1 1 1</scale>
            <uri>model://iai_avatar_description/avatars/MetaHuman/meshes/fbx/upperarm_r.fbx</uri>
          </mesh>
        </geometry>
      </visual>
    </link>
    <joint name="upperarm_r_to_lowerarm_r_yaw" type="revolute">
      <pose relative_to="upperarm_r">-0.2383 0 0 0 -0 0</pose>
      <parent>upperarm_r</parent>
      <child>lowerarm_r_yaw</child>
      <axis>
        <xyz>0 0 1</xyz>
        <limit>
          <lower>0</lower>
          <upper>0.548</upper>
          <effort>1000</effort>
          <velocity>0.5</velocity>
        </limit>
        <dynamics>
          <damping>1</damping>
          <friction>0.0001</friction>
          <spring_reference>0</spring_reference>
          <spring_stiffness>0</spring_stiffness>
        </dynamics>
      </axis>
    </joint>
    <link name="lowerarm_r_yaw">
      <pose relative_to="upperarm_r_to_lowerarm_r_yaw">0 0 0 0 -0 0</pose>
      <inertial>
        <pose>0 0 0 0 -0 0</pose>
        <mass>1.39</mass>
        <inertia>
          <ixx>0.4</ixx>
          <ixy>0</ixy>
          <ixz>0</ixz>
          <iyy>0.4</iyy>
          <iyz>0</iyz>
          <izz>0.2</izz>
        </inertia>
      </inertial>
    </link>
    <joint name="lowerarm_r_yaw_to_lowerarm_r_pitch" type="revolute">
      <pose relative_to="lowerarm_r_yaw">0 0 0 0 -0 0</pose>
      <parent>lowerarm_r_yaw</parent>
      <child>lowerarm_r_pitch</child>
      <axis>
        <xyz>0 1 0</xyz>
        <limit>
          <lower>-1.5708</lower>
          <upper>2.44346</upper>
          <effort>1</effort>
          <velocity>1</velocity>
        </limit>
        <dynamics>
          <spring_reference>0</spring_reference>
          <spring_stiffness>0</spring_stiffness>
        </dynamics>
      </axis>
    </joint>
    <link name="lowerarm_r_pitch">
      <pose relative_to="lowerarm_r_yaw_to_lowerarm_r_pitch">0 0 0 0 -0 0</pose>
      <inertial>
        <pose>0 0 0 0 -0 0</pose>
        <mass>1.39</mass>
        <inertia>
          <ixx>0.4</ixx>
          <ixy>0</ixy>
          <ixz>0</ixz>
          <iyy>0.4</iyy>
          <iyz>0</iyz>
          <izz>0.2</izz>
        </inertia>
      </inertial>
    </link>
    <joint name="lowerarm_r_pitch_to_lowerarm_r" type="revolute">
      <pose relative_to="lowerarm_r_pitch">0 0 0 0 -0 0</pose>
      <parent>lowerarm_r_pitch</parent>
      <child>lowerarm_r</child>
      <axis>
        <xyz>1 0 0</xyz>
        <limit>
          <lower>-1.5708</lower>
          <upper>2.44346</upper>
          <effort>1</effort>
          <velocity>1</velocity>
        </limit>
        <dynamics>
          <spring_reference>0</spring_reference>
          <spring_stiffness>0</spring_stiffness>
        </dynamics>
      </axis>
    </joint>
    <link name="lowerarm_r">
      <pose relative_to="lowerarm_r_pitch_to_lowerarm_r">0 0 0 0 -0 0</pose>
      <inertial>
        <pose>0 0 0 0 -0 0</pose>
        <mass>1.39</mass>
        <inertia>
          <ixx>0.4</ixx>
          <ixy>0</ixy>
          <ixz>0</ixz>
          <iyy>0.4</iyy>
          <iyz>0</iyz>
          <izz>0.2</izz>
        </inertia>
      </inertial>
      <collision name="lowerarm_r_collision">
        <pose>0 0 0 0 -0 0</pose>
        <geometry>
          <mesh>
            <scale>1 1 1</scale>
            <uri>model://iai_avatar_description/avatars/MetaHuman/meshes/fbx/lowerarm_r.fbx</uri>
          </mesh>
        </geometry>
      </collision>
      <visual name="lowerarm_r_visual">
        <pose>0 0 0 0 -0 0</pose>
        <geometry>
          <mesh>
            <scale>1 1 1</scale>
            <uri>model://iai_avatar_description/avatars/MetaHuman/meshes/fbx/lowerarm_r.fbx</uri>
          </mesh>
        </geometry>
      </visual>
    </link>
    <joint name="lowerarm_r_to_hand_r" type="revolute">
      <pose relative_to="lowerarm_r">-0.22 0 0 -1.2351 0.1883 -0.2033</pose>
      <parent>lowerarm_r</parent>
      <child>hand_r_yaw</child>
      <axis>
        <xyz>1 0 0</xyz>
        <limit>
          <lower>-1e+16</lower>
          <upper>1e+16</upper>
        </limit>
        <dynamics>
          <damping>1</damping>
          <friction>0.0001</friction>
          <spring_reference>0</spring_reference>
          <spring_stiffness>0</spring_stiffness>
        </dynamics>
      </axis>
    </joint>
    <link name="hand_r_yaw">
      <pose relative_to="lowerarm_r_to_hand_r">0 0 0 0 -0 0</pose>
      <inertial>
        <pose>0 0 0 0 -0 0</pose>
        <mass>1.15</mass>
        <inertia>
          <ixx>0.4</ixx>
          <ixy>0</ixy>
          <ixz>0</ixz>
          <iyy>0.4</iyy>
          <iyz>0</iyz>
          <izz>0.2</izz>
        </inertia>
      </inertial>
    </link>
    <joint name="hand_r_yaw_to_hand_r_pitch" type="revolute">
      <pose relative_to="hand_r_yaw">0 0 0 0 -0 0</pose>
      <parent>hand_r_yaw</parent>
      <child>hand_r_pitch</child>
      <axis>
        <xyz>0 1 0</xyz>
        <limit>
          <lower>-1.5708</lower>
          <upper>2.44346</upper>
          <effort>1</effort>
          <velocity>1</velocity>
        </limit>
        <dynamics>
          <spring_reference>0</spring_reference>
          <spring_stiffness>0</spring_stiffness>
        </dynamics>
      </axis>
    </joint>
    <link name="hand_r_pitch">
      <pose relative_to="hand_r_yaw_to_hand_r_pitch">0 0 0 0 -0 0</pose>
      <inertial>
        <pose>0 0 0 0 -0 0</pose>
        <mass>1.15</mass>
        <inertia>
          <ixx>0.4</ixx>
          <ixy>0</ixy>
          <ixz>0</ixz>
          <iyy>0.4</iyy>
          <iyz>0</iyz>
          <izz>0.2</izz>
        </inertia>
      </inertial>
    </link>
    <joint name="hand_r_pitch_to_hand_r" type="revolute">
      <pose relative_to="hand_r_pitch">0 0 0 0 -0 0</pose>
      <parent>hand_r_pitch</parent>
      <child>hand_r</child>
      <axis>
        <xyz>1 0 0</xyz>
        <limit>
          <lower>-1.5708</lower>
          <upper>2.44346</upper>
          <effort>1</effort>
          <velocity>1</velocity>
        </limit>
        <dynamics>
          <spring_reference>0</spring_reference>
          <spring_stiffness>0</spring_stiffness>
        </dynamics>
      </axis>
    </joint>
    <link name="hand_r">
      <pose relative_to="hand_r_pitch_to_hand_r">0 0 0 0 -0 0</pose>
      <inertial>
        <pose>0 0 0 0 -0 0</pose>
        <mass>1.15</mass>
        <inertia>
          <ixx>0.4</ixx>
          <ixy>0</ixy>
          <ixz>0</ixz>
          <iyy>0.4</iyy>
          <iyz>0</iyz>
          <izz>0.2</izz>
        </inertia>
      </inertial>
      <collision name="hand_r_collision">
        <pose>0 0 0 0 -0 0</pose>
        <geometry>
          <mesh>
            <scale>1 1 1</scale>
            <uri>model://iai_avatar_description/avatars/MetaHuman/meshes/fbx/hand_r.fbx</uri>
          </mesh>
        </geometry>
      </collision>
      <visual name="hand_r_visual">
        <pose>0 0 0 0 -0 0</pose>
        <geometry>
          <mesh>
            <scale>1 1 1</scale>
            <uri>model://iai_avatar_description/avatars/MetaHuman/meshes/fbx/hand_r.fbx</uri>
          </mesh>
        </geometry>
      </visual>
    </link>
    <joint name="spine_05_to_neck_01" type="revolute">
      <pose relative_to="spine_05">0.1062 0 0 0 -0 0</pose>
      <parent>spine_05</parent>
      <child>neck_01</child>
      <axis>
        <xyz>1 0 0</xyz>
        <limit>
          <lower>-1.22173</lower>
          <upper>1.22173</upper>
          <effort>1</effort>
          <velocity>1</velocity>
        </limit>
        <dynamics>
          <damping>1</damping>
          <friction>0.0001</friction>
          <spring_reference>0</spring_reference>
          <spring_stiffness>0</spring_stiffness>
        </dynamics>
      </axis>
    </joint>
    <link name="neck_01">
      <pose relative_to="spine_05_to_neck_01">0 0 0 0 -0 0</pose>
      <inertial>
        <pose>0 0 0 0 -0 0</pose>
        <mass>1.39</mass>
        <inertia>
          <ixx>0.4</ixx>
          <ixy>0</ixy>
          <ixz>0</ixz>
          <iyy>0.4</iyy>
          <iyz>0</iyz>
          <izz>0.2</izz>
        </inertia>
      </inertial>
    </link>
    <joint name="neck_01_to_neck_02" type="revolute">
      <pose relative_to="neck_01">0.053165 0 0 0 -0 0</pose>
      <parent>neck_01</parent>
      <child>neck_02</child>
      <axis>
        <xyz>0 0 1</xyz>
        <limit>
          <lower>-1.5708</lower>
          <upper>0.959931</upper>
          <effort>1</effort>
          <velocity>1</velocity>
        </limit>
        <dynamics>
          <damping>1</damping>
          <friction>0.0001</friction>
          <spring_reference>0</spring_reference>
          <spring_stiffness>0</spring_stiffness>
        </dynamics>
      </axis>
    </joint>
    <link name="neck_02">
      <pose relative_to="neck_01_to_neck_02">0 0 0 0 -0 0</pose>
      <inertial>
        <pose>0 0 0 0 -0 0</pose>
        <mass>1.34</mass>
        <inertia>
          <ixx>0.4</ixx>
          <ixy>0</ixy>
          <ixz>0</ixz>
          <iyy>0.4</iyy>
          <iyz>0</iyz>
          <izz>0.2</izz>
        </inertia>
      </inertial>
    </link>
    <joint name="neck_02_to_head_yaw" type="revolute">
      <pose relative_to="neck_02">0.052795 0 0 0 -0 0</pose>
      <parent>neck_02</parent>
      <child>head_yaw</child>
      <axis>
        <xyz>0 1 0</xyz>
        <limit>
          <lower>-0.610865</lower>
          <upper>0.610865</upper>
          <effort>1</effort>
          <velocity>1</velocity>
        </limit>
        <dynamics>
          <damping>1</damping>
          <friction>0.0001</friction>
          <spring_reference>0</spring_reference>
          <spring_stiffness>0</spring_stiffness>
        </dynamics>
      </axis>
    </joint>
    <link name="head_yaw">
      <pose relative_to="neck_02_to_head_yaw">0 0 0 0 -0 0</pose>
      <inertial>
        <pose>0 0 0 0 -0 0</pose>
        <mass>3.34</mass>
        <inertia>
          <ixx>0.4</ixx>
          <ixy>0</ixy>
          <ixz>0</ixz>
          <iyy>0.4</iyy>
          <iyz>0</iyz>
          <izz>0.2</izz>
        </inertia>
      </inertial>
    </link>
    <joint name="head_yaw_to_head_pitch" type="revolute">
      <pose relative_to="head_yaw">0 0 0 0 -0 0</pose>
      <parent>head_yaw</parent>
      <child>head_pitch</child>
      <axis>
        <xyz>0 1 0</xyz>
        <limit>
          <lower>-1.5708</lower>
          <upper>2.44346</upper>
          <effort>1</effort>
          <velocity>1</velocity>
        </limit>
        <dynamics>
          <spring_reference>0</spring_reference>
          <spring_stiffness>0</spring_stiffness>
        </dynamics>
      </axis>
    </joint>
    <link name="head_pitch">
      <pose relative_to="head_yaw_to_head_pitch">0 0 0 0 -0 0</pose>
      <inertial>
        <pose>0 0 0 0 -0 0</pose>
        <mass>3.34</mass>
        <inertia>
          <ixx>0.4</ixx>
          <ixy>0</ixy>
          <ixz>0</ixz>
          <iyy>0.4</iyy>
          <iyz>0</iyz>
          <izz>0.2</izz>
        </inertia>
      </inertial>
    </link>
    <joint name="head_pitch_to_head" type="revolute">
      <pose relative_to="head_pitch">0 0 0 0 -0 0</pose>
      <parent>head_pitch</parent>
      <child>head</child>
      <axis>
        <xyz>1 0 0</xyz>
        <limit>
          <lower>-1.5708</lower>
          <upper>2.44346</upper>
          <effort>1</effort>
          <velocity>1</velocity>
        </limit>
        <dynamics>
          <spring_reference>0</spring_reference>
          <spring_stiffness>0</spring_stiffness>
        </dynamics>
      </axis>
    </joint>
    <link name="head">
      <pose relative_to="head_pitch_to_head">0 0 0 0 -0 0</pose>
      <inertial>
        <pose>0 0 0 0 -0 0</pose>
        <mass>3.34</mass>
        <inertia>
          <ixx>0.4</ixx>
          <ixy>0</ixy>
          <ixz>0</ixz>
          <iyy>0.4</iyy>
          <iyz>0</iyz>
          <izz>0.2</izz>
        </inertia>
      </inertial>
      <collision name="head_collision">
        <pose>0 0 0 0 -0 0</pose>
        <geometry>
          <mesh>
            <scale>1 1 1</scale>
            <uri>model://iai_avatar_description/avatars/MetaHuman/meshes/fbx/head.fbx</uri>
          </mesh>
        </geometry>
      </collision>
      <visual name="head_visual">
        <pose>0 0 0 0 -0 0</pose>
        <geometry>
          <mesh>
            <scale>1 1 1</scale>
            <uri>model://iai_avatar_description/avatars/MetaHuman/meshes/fbx/head.fbx</uri>
          </mesh>
        </geometry>
      </visual>
    </link>
    <joint name="pelvis_to_thigh_l" type="revolute">
      <pose relative_to="pelvis">-0.03036 0.003211 -0.0957 0 -0 0</pose>
      <parent>pelvis</parent>
      <child>thigh_l</child>
      <axis>
        <xyz>1 0 0</xyz>
        <limit>
          <lower>-1e+16</lower>
          <upper>1e+16</upper>
        </limit>
        <dynamics>
          <damping>1</damping>
          <friction>0.0001</friction>
          <spring_reference>0</spring_reference>
          <spring_stiffness>0</spring_stiffness>
        </dynamics>
      </axis>
    </joint>
    <link name="thigh_l">
      <pose relative_to="pelvis_to_thigh_l">0 0 0 0 -0 0</pose>
      <inertial>
        <pose>0 0 0 0 -0 0</pose>
        <mass>5.5</mass>
        <inertia>
          <ixx>0.4</ixx>
          <ixy>0</ixy>
          <ixz>0</ixz>
          <iyy>0.4</iyy>
          <iyz>0</iyz>
          <izz>0.2</izz>
        </inertia>
      </inertial>
      <collision name="thigh_l_collision">
        <pose>0 0 0 0 -0 0</pose>
        <geometry>
          <mesh>
            <scale>1 1 1</scale>
            <uri>model://iai_avatar_description/avatars/MetaHuman/meshes/fbx/thigh_l.fbx</uri>
          </mesh>
        </geometry>
      </collision>
      <visual name="thigh_l_visual">
        <pose>0 0 0 0 -0 0</pose>
        <geometry>
          <mesh>
            <scale>1 1 1</scale>
            <uri>model://iai_avatar_description/avatars/MetaHuman/meshes/fbx/thigh_l.fbx</uri>
          </mesh>
        </geometry>
      </visual>
    </link>
    <joint name="thigh_l_to_calf_l" type="revolute">
      <pose relative_to="thigh_l">-0.4024 0 0 0 -0 0</pose>
      <parent>thigh_l</parent>
      <child>calf_l</child>
      <axis>
        <xyz>1 0 0</xyz>
        <limit>
          <lower>-1e+16</lower>
          <upper>1e+16</upper>
        </limit>
        <dynamics>
          <damping>1</damping>
          <friction>0.0001</friction>
          <spring_reference>0</spring_reference>
          <spring_stiffness>0</spring_stiffness>
        </dynamics>
      </axis>
    </joint>
    <link name="calf_l">
      <pose relative_to="thigh_l_to_calf_l">0 0 0 0 -0 0</pose>
      <inertial>
        <pose>0 0 0 0 -0 0</pose>
        <mass>3.37</mass>
        <inertia>
          <ixx>0.4</ixx>
          <ixy>0</ixy>
          <ixz>0</ixz>
          <iyy>0.4</iyy>
          <iyz>0</iyz>
          <izz>0.2</izz>
        </inertia>
      </inertial>
      <collision name="calf_l_collision">
        <pose>0 0 0 0 -0 0</pose>
        <geometry>
          <mesh>
            <scale>1 1 1</scale>
            <uri>model://iai_avatar_description/avatars/MetaHuman/meshes/fbx/calf_l.fbx</uri>
          </mesh>
        </geometry>
      </collision>
      <visual name="calf_l_visual">
        <pose>0 0 0 0 -0 0</pose>
        <geometry>
          <mesh>
            <scale>1 1 1</scale>
            <uri>model://iai_avatar_description/avatars/MetaHuman/meshes/fbx/calf_l.fbx</uri>
          </mesh>
        </geometry>
      </visual>
    </link>
    <joint name="calf_l_to_foot_l" type="revolute">
      <pose relative_to="calf_l">-0.3674 0 0 0 -0 0</pose>
      <parent>calf_l</parent>
      <child>foot_l</child>
      <axis>
        <xyz>1 0 0</xyz>
        <limit>
          <lower>-1e+16</lower>
          <upper>1e+16</upper>
        </limit>
        <dynamics>
          <damping>1</damping>
          <friction>0.0001</friction>
          <spring_reference>0</spring_reference>
          <spring_stiffness>0</spring_stiffness>
        </dynamics>
      </axis>
    </joint>
    <link name="foot_l">
      <pose relative_to="calf_l_to_foot_l">0 0 0 0 -0 0</pose>
      <inertial>
        <pose>0 0 0 0 -0 0</pose>
        <mass>1.12</mass>
        <inertia>
          <ixx>0.4</ixx>
          <ixy>0</ixy>
          <ixz>0</ixz>
          <iyy>0.4</iyy>
          <iyz>0</iyz>
          <izz>0.2</izz>
        </inertia>
      </inertial>
      <collision name="foot_l_collision">
        <pose>0 0 0 0 -0 0</pose>
        <geometry>
          <mesh>
            <scale>1 1 1</scale>
            <uri>model://iai_avatar_description/avatars/MetaHuman/meshes/fbx/foot_l.fbx</uri>
          </mesh>
        </geometry>
      </collision>
      <visual name="foot_l_visual">
        <pose>0 0 0 0 -0 0</pose>
        <geometry>
          <mesh>
            <scale>1 1 1</scale>
            <uri>model://iai_avatar_description/avatars/MetaHuman/meshes/fbx/foot_l.fbx</uri>
          </mesh>
        </geometry>
      </visual>
    </link>
    <joint name="pelvis_to_thigh_r" type="revolute">
      <pose relative_to="pelvis">-0.030363 0.003258 0.095721 0 0 -3.14159</pose>
      <parent>pelvis</parent>
      <child>thigh_r</child>
      <axis>
        <xyz>1 0 0</xyz>
        <limit>
          <lower>-1e+16</lower>
          <upper>1e+16</upper>
        </limit>
        <dynamics>
          <damping>1</damping>
          <friction>0.0001</friction>
          <spring_reference>0</spring_reference>
          <spring_stiffness>0</spring_stiffness>
        </dynamics>
      </axis>
    </joint>
    <link name="thigh_r">
      <pose relative_to="pelvis_to_thigh_r">0 0 0 0 -0 0</pose>
      <inertial>
        <pose>0 0 0 0 -0 0</pose>
        <mass>5.5</mass>
        <inertia>
          <ixx>0.4</ixx>
          <ixy>0</ixy>
          <ixz>0</ixz>
          <iyy>0.4</iyy>
          <iyz>0</iyz>
          <izz>0.2</izz>
        </inertia>
      </inertial>
      <collision name="thigh_r_collision">
        <pose>0 0 0 0 -0 0</pose>
        <geometry>
          <mesh>
            <scale>1 1 1</scale>
            <uri>model://iai_avatar_description/avatars/MetaHuman/meshes/fbx/thigh_r.fbx</uri>
          </mesh>
        </geometry>
      </collision>
      <visual name="thigh_r_visual">
        <pose>0 0 0 0 -0 0</pose>
        <geometry>
          <mesh>
            <scale>1 1 1</scale>
            <uri>model://iai_avatar_description/avatars/MetaHuman/meshes/fbx/thigh_r.fbx</uri>
          </mesh>
        </geometry>
      </visual>
    </link>
    <joint name="thigh_r_to_calf_r" type="revolute">
      <pose relative_to="thigh_r">0.405526 0 0 0 -0 0</pose>
      <parent>thigh_r</parent>
      <child>calf_r</child>
      <axis>
        <xyz>1 0 0</xyz>
        <limit>
          <lower>-1e+16</lower>
          <upper>1e+16</upper>
        </limit>
        <dynamics>
          <damping>1</damping>
          <friction>0.0001</friction>
          <spring_reference>0</spring_reference>
          <spring_stiffness>0</spring_stiffness>
        </dynamics>
      </axis>
    </joint>
    <link name="calf_r">
      <pose relative_to="thigh_r_to_calf_r">0 0 0 0 -0 0</pose>
      <inertial>
        <pose>0 0 0 0 -0 0</pose>
        <mass>3.37</mass>
        <inertia>
          <ixx>0.4</ixx>
          <ixy>0</ixy>
          <ixz>0</ixz>
          <iyy>0.4</iyy>
          <iyz>0</iyz>
          <izz>0.2</izz>
        </inertia>
      </inertial>
      <collision name="calf_r_collision">
        <pose>0 0 0 0 -0 0</pose>
        <geometry>
          <mesh>
            <scale>1 1 1</scale>
            <uri>model://iai_avatar_description/avatars/MetaHuman/meshes/fbx/calf_r.fbx</uri>
          </mesh>
        </geometry>
      </collision>
      <visual name="calf_r_visual">
        <pose>0 0 0 0 -0 0</pose>
        <geometry>
          <mesh>
            <scale>1 1 1</scale>
            <uri>model://iai_avatar_description/avatars/MetaHuman/meshes/fbx/calf_r.fbx</uri>
          </mesh>
        </geometry>
      </visual>
    </link>
    <joint name="calf_r_to_foot_r" type="revolute">
      <pose relative_to="calf_r">0.3674 0 0 0 -0 0</pose>
      <parent>calf_r</parent>
      <child>foot_r</child>
      <axis>
        <xyz>1 0 0</xyz>
        <limit>
          <lower>-1e+16</lower>
          <upper>1e+16</upper>
        </limit>
        <dynamics>
          <damping>1</damping>
          <friction>0.0001</friction>
          <spring_reference>0</spring_reference>
          <spring_stiffness>0</spring_stiffness>
        </dynamics>
      </axis>
    </joint>
    <link name="foot_r">
      <pose relative_to="calf_r_to_foot_r">0 0 0 0 -0 0</pose>
      <inertial>
        <pose>0 0 0 0 -0 0</pose>
        <mass>1.12</mass>
        <inertia>
          <ixx>0.4</ixx>
          <ixy>0</ixy>
          <ixz>0</ixz>
          <iyy>0.4</iyy>
          <iyz>0</iyz>
          <izz>0.2</izz>
        </inertia>
      </inertial>
      <collision name="foot_r_collision">
        <pose>0 0 0 0 -0 0</pose>
        <geometry>
          <mesh>
            <scale>1 1 1</scale>
            <uri>model://iai_avatar_description/avatars/MetaHuman/meshes/fbx/foot_r.fbx</uri>
          </mesh>
        </geometry>
      </collision>
      <visual name="foot_r_visual">
        <pose>0 0 0 0 -0 0</pose>
        <geometry>
          <mesh>
            <scale>1 1 1</scale>
            <uri>model://iai_avatar_description/avatars/MetaHuman/meshes/fbx/foot_r.fbx</uri>
          </mesh>
        </geometry>
      </visual>
    </link>
  </model>
</sdf>
